<?xml version="1.0"?>
<robot name="hubert">

  <link name="base_link">
    <visual>
      <geometry>
        <box size="0.055 0.02 0.02"/>
      </geometry>
      <origin rpy="0 1.57075 0" xyz=" 0 0 0.0275"/>
    </visual>
    <collision>
	    <geometry>
		    <box size="0.055 0.02 0.02"/>
	    </geometry>
	    <origin rpy="0 1.57075 0" xyz=" 0 0 0.0275"/>
    </collision>
  </link>

  <link name="robot_body">
    <visual>
      <geometry>
        <box size="0.315 0.02 0.02"/>
      </geometry>
      <origin rpy="0 1.57075 0" xyz="0 0 0.163"/>
    </visual>
    <collision>
      <geometry>
        <box size="0.315 0.02 0.02"/>
      </geometry>
      <origin rpy="0 1.57075 0" xyz="0 0 0.163"/>
    </collision>
  </link>

  <link name="robot_shoulder">
    <visual>
      <geometry>
        <box size="0.216 0.02 0.02"/>
      </geometry>
      <origin rpy=" 0 0 1.57075" xyz="0 0 0"/>
    </visual>
    <collision>
      <geometry>
        <box size="0.216 0.02 0.02"/>
      </geometry>
      <origin rpy=" 0 0 1.57075" xyz="0 0 0"/>
    </collision>
  </link>

  <link name="robot_arm">
    <visual>
      <geometry>
        <box size="0.088 0.02 0.02"/>
      </geometry>
      <origin rpy=" 0 0 1.57075" xyz="0 -0.044 0"/>
    </visual>
    <collision>
    <geometry>
        <box size="0.088 0.02 0.02"/>
      </geometry>
      <origin rpy=" 0 0 1.57075" xyz="0 -0.044 0"/>
    </collision>
  </link>

  <link name="robot_elbow">
    <visual>
      <geometry>
        <box size="0.204 0.02 0.02"/>
      </geometry>
      <origin rpy=" 0 0 1.57075" xyz="0 -.102 0"/>
    </visual>
    <collision>
    <geometry>
        <box size="0.204 0.02 0.02"/>
      </geometry>
      <origin rpy=" 0 0 1.57075" xyz="0 -.102 0"/>
    </collision>
  </link>

  <link name="end_effector">
    <visual>
      <geometry>
        <box size="0.204 0.02 0.02"/>
      </geometry>
      <origin rpy=" 0 0 1.57075" xyz="0 -.102 0"/>
    </visual>
    <collision>
    <geometry>
        <box size="0.15 0.02 0.02"/>
      </geometry>
      <origin rpy=" 0 0 1.57075" xyz="0 -.075 0"/>
    </collision>
  </link>

  <joint name="base_joint" type="revolute">
    <axis xyz="0 0 1"/>
    <limit effort="1000.0" lower="0" upper="3.14" velocity="0.5"/>
    <parent link="base_link"/>
    <child link="robot_body"/>
    <origin xyz="0 0 0.055"/>
  </joint>

  <joint name="body_to_shoulder" type="fixed">
    <parent link="robot_body"/>
    <child link="robot_shoulder"/>
    <origin xyz="0 0 0.315"/>
  </joint>

  <joint name="shoulder_joint" type="revolute">
    <axis xyz="0 0 1"/>
    <limit effort="1000.0" lower="0" upper="3.14" velocity="0.5"/>
    <parent link="robot_shoulder"/>
    <child link="robot_arm"/>
    <origin rpy=" 1.57075 0 0" xyz="0.034 -0.108 0"/>
  </joint>
  
  <joint name="elbow_joint" type="revolute">
    <axis xyz="0 0 1"/>
    <limit effort="1000.0" lower="-0" upper="1.57075" velocity="0.5"/>
    <parent link="robot_arm"/>
    <child link="robot_elbow"/>
    <origin rpy=" 0 0 0" xyz="0.015 -0.088 -0.005"/>
  </joint>

  <joint name="end_effector_joint" type="fixed">
    <axis xyz="0 0 1"/>
    <parent link="robot_elbow"/>
    <child link="end_effector"/>
    <origin rpy=" 0 0 0" xyz="0.015 -0.15 -0.005"/>
  </joint>
</robot>
